<?xml version="1.0" ?>
<!-- =================================================================================== -->
<!-- |    This document was autogenerated by xacro from /home/mustar/catkin_ws/src/turtlebot/turtlebot_description/robots/kobuki_hexagons_astra_origin.urdf.xacro | -->
<!-- |    EDITING THIS FILE BY HAND IS NOT RECOMMENDED                                 | -->
<!-- =================================================================================== -->
<!--
    - Base      : kobuki
    - Stacks    : hexagons
    - 3d Sensor : astra
-->
<robot name="turtlebot" xmlns:xacro="http://ros.org/wiki/xacro">
    <!-- 
    These properties must be observed by any machine
    that wants to be defined as a turtlebot. Refer
    to the REP for more details.
    
    http://www.ros.org/reps/rep-0119.html
   -->
    <!-- 
    These properties must be observed by any machine
    that wants to be defined as a turtlebot. Refer
    to the REP for more details.
    
    http://www.ros.org/reps/rep-0119.html
   -->
    <material name="White">
        <color rgba="0.87 0.90 0.87 1.0" />
    </material>
    <material name="Black">
        <color rgba="0.08 0.08 0.08 1.0" />
    </material>
    <material name="Gray">
        <color rgba="0.2 0.2 0.21 1.0" />
    </material>
    <material name="Green">
        <color rgba="0.22 0.32 0.14 1.0" />
    </material>
    <!-- As we don't have here a turtlebot base, add a base_link link as its location reference -->
    <!--<link name="base_link"/>-->
    <link name="arm_base_link" />
    <joint name="arm_base_joint" type="fixed">
        <origin xyz="0.1 0.011 0.435" />
        <parent link="base_link" />
        <child link="arm_base_link" />
    </joint>
    <joint name="arm_1_servo_joint" type="fixed">
        <origin rpy="1.570795 0 1.570795" xyz="0 0 0" />
        <parent link="arm_base_link" />
        <child link="arm_1_servo_link" />
    </joint>
    <link name="arm_1_servo_link">
        
<inertial>
            <mass value="0.055" />
            <origin xyz="0 0 0" />
            <inertia ixx="0.000017012" ixy="0.0" ixz="0.0" iyy="0.000013258" iyz="0.0" izz="0.000009483" />
        </inertial>

        <visual>
            <origin rpy="0 0 0" xyz=" 0 0 0 " />
            <geometry>
                <mesh filename="package://mustar_arm_description/meshes/ax12_box.stl" scale="0.001 0.001 0.001" />
            </geometry>
            <material name="Black" />
        </visual>
        <collision>
            <origin rpy="0 0 0" xyz="0.0 0.0 -0.01241" />
            <geometry>
                <box size="0.025 0.038 0.04762" />
            </geometry>
        </collision>
    </link>
    <gazebo reference="arm_1_servo_link">
        <material>Gazebo/Black</material>
        <selfCollide>true</selfCollide>
        <gravity>true</gravity>
    </gazebo>
    <joint name="arm_1_F3_joint" type="revolute">
        <origin rpy="-1.570795 1.570795 3.14159" xyz="0 0.019 0" />
        <axis xyz="0 0 -1" />
        <limit effort="30" lower="-2.617" upper="2.617" velocity="1.571" />
        <dynamics friction="0.13" />
        <parent link="arm_1_servo_link" />
        <child link="arm_1_F3_link" />
    </joint>
    <link name="arm_1_F3_link">
        
<inertial>
            <mass value="0.008" />
            <origin xyz="0 0 0" />
            <inertia ixx="4.70666666667e-07" ixy="0" ixz="0" iyy="1.37933333333e-06" iyz="0" izz="1.01666666667e-06" />
        </inertial>

        <visual>
            <origin rpy="0 0 0" xyz=" 0 0 0 " />
            <geometry>
                <mesh filename="package://mustar_arm_description/meshes/F3.stl" scale="0.001 0.001 0.001" />
            </geometry>
            <material name="White" />
        </visual>
        <collision>
            <origin rpy="0 0 0" xyz="0.0 0.0 -0.0045" />
            <geometry>
                <box size="0.025 0.038 0.009" />
            </geometry>
        </collision>
    </link>
    <gazebo reference="arm_1_F3_link">
        <material>Gazebo/White</material>
        <selfCollide>true</selfCollide>
        <gravity>true</gravity>
    </gazebo>
    <joint name="arm_2_servo_joint" type="fixed">
        <origin rpy="0 3.14159 3.14159" xyz="0 0 -0.0375" />
        <parent link="arm_1_F3_link" />
        <child link="arm_2_servo_link" />
    </joint>
    <link name="arm_2_servo_link">
        
<inertial>
            <mass value="0.055" />
            <origin xyz="0 0 0" />
            <inertia ixx="0.000017012" ixy="0.0" ixz="0.0" iyy="0.000013258" iyz="0.0" izz="0.000009483" />
        </inertial>

        <visual>
            <origin rpy="0 0 0" xyz=" 0 0 0 " />
            <geometry>
                <mesh filename="package://mustar_arm_description/meshes/ax12_box.stl" scale="0.001 0.001 0.001" />
            </geometry>
            <material name="Black" />
        </visual>
        <collision>
            <origin rpy="0 0 0" xyz="0.0 0.0 -0.01241" />
            <geometry>
                <box size="0.025 0.038 0.04762" />
            </geometry>
        </collision>
    </link>
    <gazebo reference="arm_2_servo_link">
        <material>Gazebo/Black</material>
        <selfCollide>true</selfCollide>
        <gravity>true</gravity>
    </gazebo>
    <joint name="arm_2_F4_joint" type="revolute">
        <origin rpy="0 0 0" xyz="0 0 0" />
        <axis xyz="0 1 0" />
        <limit effort="30" lower="-2.617" upper="2.617" velocity="1.571" />
        <dynamics friction="0.13" />
        <parent link="arm_2_servo_link" />
        <child link="arm_2_F4_link" />
    </joint>
    <link name="arm_2_F4_link">
        
<inertial>
            <mass value="0.016" />
            <origin xyz="0 0 0" />
            <inertia ixx="6.67866666667e-06" ixy="0" ixz="0" iyy="4.18166666667e-06" iyz="0" izz="8.76966666667e-06" />
        </inertial>

        <visual>
            <origin rpy="0 0 0" xyz=" 0 0 0 " />
            <geometry>
                <mesh filename="package://mustar_arm_description/meshes/F4.stl" scale="0.001 0.001 0.001" />
            </geometry>
            <material name="White" />
        </visual>
        <collision>
            <origin rpy="0 0 0" xyz="0.0 0.0 0.0215" />
            <geometry>
                <box size="0.028 0.0485 0.065" />
            </geometry>
        </collision>
    </link>
    <gazebo reference="arm_2_F4_link">
        <material>Gazebo/White</material>
        <selfCollide>true</selfCollide>
        <gravity>true</gravity>
    </gazebo>
    <joint name="arm_2_F3_joint" type="fixed">
        <origin rpy="0 3.14159 0" xyz="0 0 0.0525" />
        <parent link="arm_2_F4_link" />
        <child link="arm_2_F3_link" />
    </joint>
    <link name="arm_2_F3_link">
        
<inertial>
            <mass value="0.005" />
            <origin xyz="0 0 0" />
            <inertia ixx="2.94166666667e-07" ixy="0" ixz="0" iyy="8.62083333333e-07" iyz="0" izz="6.35416666667e-07" />
        </inertial>

        <visual>
            <origin rpy="0 0 0" xyz=" 0 0 0 " />
            <geometry>
                <mesh filename="package://mustar_arm_description/meshes/F3.stl" scale="0.001 0.001 0.001" />
            </geometry>
            <material name="White" />
        </visual>
        <collision>
            <origin rpy="0 0 0" xyz="0.0 0.0 -0.0045" />
            <geometry>
                <box size="0.025 0.038 0.009" />
            </geometry>
        </collision>
    </link>
    <gazebo reference="arm_2_F3_link">
        <material>Gazebo/White</material>
        <selfCollide>true</selfCollide>
        <gravity>true</gravity>
    </gazebo>
    <joint name="arm_3_servo_joint" type="fixed">
        <origin rpy="0 3.14159 0" xyz="0 0 -0.0375" />
        <parent link="arm_2_F3_link" />
        <child link="arm_3_servo_link" />
    </joint>
    <link name="arm_3_servo_link">
        
<inertial>
            <mass value="0.055" />
            <origin xyz="0 0 0" />
            <inertia ixx="0.000017012" ixy="0.0" ixz="0.0" iyy="0.000013258" iyz="0.0" izz="0.000009483" />
        </inertial>

        <visual>
            <origin rpy="0 0 0" xyz=" 0 0 0 " />
            <geometry>
                <mesh filename="package://mustar_arm_description/meshes/ax12_box.stl" scale="0.001 0.001 0.001" />
            </geometry>
            <material name="Black" />
        </visual>
        <collision>
            <origin rpy="0 0 0" xyz="0.0 0.0 -0.01241" />
            <geometry>
                <box size="0.025 0.038 0.04762" />
            </geometry>
        </collision>
    </link>
    <gazebo reference="arm_3_servo_link">
        <material>Gazebo/Black</material>
        <selfCollide>true</selfCollide>
        <gravity>true</gravity>
    </gazebo>
    <joint name="arm_3_F4_joint" type="revolute">
        <origin rpy="0 0 0" xyz="0 0 0" />
        <axis xyz="0 1 0" />
        <limit effort="30" lower="-2.617" upper="2.617" velocity="1.571" />
        <dynamics friction="0.13" />
        <parent link="arm_3_servo_link" />
        <child link="arm_3_F4_link" />
    </joint>
    <link name="arm_3_F4_link">
        
<inertial>
            <mass value="0.016" />
            <origin xyz="0 0 0" />
            <inertia ixx="6.67866666667e-06" ixy="0" ixz="0" iyy="4.18166666667e-06" iyz="0" izz="8.76966666667e-06" />
        </inertial>

        <visual>
            <origin rpy="0 0 0" xyz=" 0 0 0 " />
            <geometry>
                <mesh filename="package://mustar_arm_description/meshes/F4.stl" scale="0.001 0.001 0.001" />
            </geometry>
            <material name="White" />
        </visual>
        <collision>
            <origin rpy="0 0 0" xyz="0.0 0.0 0.0215" />
            <geometry>
                <box size="0.028 0.0485 0.065" />
            </geometry>
        </collision>
    </link>
    <gazebo reference="arm_3_F4_link">
        <material>Gazebo/White</material>
        <selfCollide>true</selfCollide>
        <gravity>true</gravity>
    </gazebo>
    <joint name="arm_3_F3_joint" type="fixed">
        <origin rpy="0 3.14159 3.14159" xyz="0 0 0.0525" />
        <parent link="arm_3_F4_link" />
        <child link="arm_3_F3_link" />
    </joint>
    <link name="arm_3_F3_link">
        
<inertial>
            <mass value="0.005" />
            <origin xyz="0 0 0" />
            <inertia ixx="2.94166666667e-07" ixy="0" ixz="0" iyy="8.62083333333e-07" iyz="0" izz="6.35416666667e-07" />
        </inertial>

        <visual>
            <origin rpy="0 0 0" xyz=" 0 0 0 " />
            <geometry>
                <mesh filename="package://mustar_arm_description/meshes/F3.stl" scale="0.001 0.001 0.001" />
            </geometry>
            <material name="White" />
        </visual>
        <collision>
            <origin rpy="0 0 0" xyz="0.0 0.0 -0.0045" />
            <geometry>
                <box size="0.025 0.038 0.009" />
            </geometry>
        </collision>
    </link>
    <gazebo reference="arm_3_F3_link">
        <material>Gazebo/White</material>
        <selfCollide>true</selfCollide>
        <gravity>true</gravity>
    </gazebo>
    <joint name="arm_4_servo_joint" type="fixed">
        <origin rpy="0 3.14159 0" xyz="0 0 -0.0375" />
        <parent link="arm_3_F3_link" />
        <child link="arm_4_servo_link" />
    </joint>
    <link name="arm_4_servo_link">
        
<inertial>
            <mass value="0.055" />
            <origin xyz="0 0 0" />
            <inertia ixx="0.000017012" ixy="0.0" ixz="0.0" iyy="0.000013258" iyz="0.0" izz="0.000009483" />
        </inertial>

        <visual>
            <origin rpy="0 0 0" xyz=" 0 0 0 " />
            <geometry>
                <mesh filename="package://mustar_arm_description/meshes/ax12_box.stl" scale="0.001 0.001 0.001" />
            </geometry>
            <material name="Black" />
        </visual>
        <collision>
            <origin rpy="0 0 0" xyz="0.0 0.0 -0.01241" />
            <geometry>
                <box size="0.025 0.038 0.04762" />
            </geometry>
        </collision>
    </link>
    <gazebo reference="arm_4_servo_link">
        <material>Gazebo/Black</material>
        <selfCollide>true</selfCollide>
        <gravity>true</gravity>
    </gazebo>
    <joint name="arm_4_F3_joint" type="revolute">
        <origin rpy="-1.570795 -1.570795 3.14159" xyz="0 0.019 0" />
        <axis xyz="0 0 -1" />
        <limit effort="30" lower="-2.617" upper="2.617" velocity="1.571" />
        <dynamics friction="0.13" />
        <parent link="arm_4_servo_link" />
        <child link="arm_4_F3_link" />
    </joint>
    <link name="arm_4_F3_link">
        
<inertial>
            <mass value="0.008" />
            <origin xyz="0 0 0" />
            <inertia ixx="4.70666666667e-07" ixy="0" ixz="0" iyy="1.37933333333e-06" iyz="0" izz="1.01666666667e-06" />
        </inertial>

        <visual>
            <origin rpy="0 0 0" xyz=" 0 0 0 " />
            <geometry>
                <mesh filename="package://mustar_arm_description/meshes/F3.stl" scale="0.001 0.001 0.001" />
            </geometry>
            <material name="White" />
        </visual>
        <collision>
            <origin rpy="0 0 0" xyz="0.0 0.0 -0.0045" />
            <geometry>
                <box size="0.025 0.038 0.009" />
            </geometry>
        </collision>
    </link>
    <gazebo reference="arm_4_F3_link">
        <material>Gazebo/White</material>
        <selfCollide>true</selfCollide>
        <gravity>true</gravity>
    </gazebo>
    <joint name="arm_5_servo_joint" type="fixed">
        <origin rpy="0 3.14159 3.14159" xyz="0 0 -0.0375" />
        <parent link="arm_4_F3_link" />
        <child link="arm_5_servo_link" />
    </joint>
    <link name="arm_5_servo_link">
        
<inertial>
            <mass value="0.055" />
            <origin xyz="0 0 0" />
            <inertia ixx="0.000017012" ixy="0.0" ixz="0.0" iyy="0.000013258" iyz="0.0" izz="0.000009483" />
        </inertial>

        <visual>
            <origin rpy="0 0 0" xyz=" 0 0 0 " />
            <geometry>
                <mesh filename="package://mustar_arm_description/meshes/ax12_box.stl" scale="0.001 0.001 0.001" />
            </geometry>
            <material name="Black" />
        </visual>
        <collision>
            <origin rpy="0 0 0" xyz="0.0 0.0 -0.01241" />
            <geometry>
                <box size="0.025 0.038 0.04762" />
            </geometry>
        </collision>
    </link>
    <gazebo reference="arm_5_servo_link">
        <material>Gazebo/Black</material>
        <selfCollide>true</selfCollide>
        <gravity>true</gravity>
    </gazebo>
    <joint name="arm_5_F3_joint" type="revolute">
        <origin rpy="-1.570795 -1.570795 3.14159" xyz="0 0.019 0" />
        <axis xyz="0 0 -1" />
        <limit effort="30" lower="-2.617" upper="2.617" velocity="1.571" />
        <dynamics friction="0.13" />
        <parent link="arm_5_servo_link" />
        <child link="arm_5_F3_link" />
    </joint>
    <link name="arm_5_F3_link">
        
<inertial>
            <mass value="0.008" />
            <origin xyz="0 0 0" />
            <inertia ixx="4.70666666667e-07" ixy="0" ixz="0" iyy="1.37933333333e-06" iyz="0" izz="1.01666666667e-06" />
        </inertial>

        <visual>
            <origin rpy="0 0 0" xyz=" 0 0 0 " />
            <geometry>
                <mesh filename="package://mustar_arm_description/meshes/F3.stl" scale="0.001 0.001 0.001" />
            </geometry>
            <material name="White" />
        </visual>
        <collision>
            <origin rpy="0 0 0" xyz="0.0 0.0 -0.0045" />
            <geometry>
                <box size="0.025 0.038 0.009" />
            </geometry>
        </collision>
    </link>
    <gazebo reference="arm_5_F3_link">
        <material>Gazebo/White</material>
        <selfCollide>true</selfCollide>
        <gravity>true</gravity>
    </gazebo>
    <joint name="arm_6_servo_joint" type="fixed">
        <origin rpy="0 3.14159 3.14159" xyz="0 0 -0.0375" />
        <parent link="arm_5_F3_link" />
        <child link="arm_6_servo_link" />
    </joint>
    <link name="arm_6_servo_link">
        
<inertial>
            <mass value="0.055" />
            <origin xyz="0 0 0" />
            <inertia ixx="0.000017012" ixy="0.0" ixz="0.0" iyy="0.000013258" iyz="0.0" izz="0.000009483" />
        </inertial>

        <visual>
            <origin rpy="0 0 0" xyz=" 0 0 0 " />
            <geometry>
                <mesh filename="package://mustar_arm_description/meshes/ax12_box.stl" scale="0.001 0.001 0.001" />
            </geometry>
            <material name="Black" />
        </visual>
        <collision>
            <origin rpy="0 0 0" xyz="0.0 0.0 -0.01241" />
            <geometry>
                <box size="0.025 0.038 0.04762" />
            </geometry>
        </collision>
    </link>
    <gazebo reference="arm_6_servo_link">
        <material>Gazebo/Black</material>
        <selfCollide>true</selfCollide>
        <gravity>true</gravity>
    </gazebo>
    <joint name="arm_6_F3_joint" type="revolute">
        <origin rpy="-1.570795 3.14159 3.14159" xyz="0 0.019 0" />
        <axis xyz="0 0 -1" />
        <limit effort="30" lower="-2.617" upper="2.617" velocity="1.571" />
        <dynamics friction="0.13" />
        <parent link="arm_6_servo_link" />
        <child link="arm_6_F3_link" />
    </joint>
    <link name="arm_6_F3_link">
        
<inertial>
            <mass value="0.008" />
            <origin xyz="0 0 0" />
            <inertia ixx="4.70666666667e-07" ixy="0" ixz="0" iyy="1.37933333333e-06" iyz="0" izz="1.01666666667e-06" />
        </inertial>

        <visual>
            <origin rpy="0 0 0" xyz=" 0 0 0 " />
            <geometry>
                <mesh filename="package://mustar_arm_description/meshes/F3.stl" scale="0.001 0.001 0.001" />
            </geometry>
            <material name="White" />
        </visual>
        <collision>
            <origin rpy="0 0 0" xyz="0.0 0.0 -0.0045" />
            <geometry>
                <box size="0.025 0.038 0.009" />
            </geometry>
        </collision>
    </link>
    <gazebo reference="arm_6_F3_link">
        <material>Gazebo/White</material>
        <selfCollide>true</selfCollide>
        <gravity>true</gravity>
        <!--<mu1>100000.0</mu1>
        <mu2>100000.0</mu2>
        <kp>100000000.0</kp>
        <kd>1.0</kd>-->
    </gazebo>
    <joint name="gripper_servo_joint" type="fixed">
        <origin rpy="3.14159 1.570795 0" xyz="-0.016 0 -0.019" />
        <parent link="arm_6_F3_link" />
        <child link="gripper_servo_link" />
    </joint>
    <link name="gripper_servo_link">
        
<inertial>
            <mass value="0.055" />
            <origin xyz="0 0 0" />
            <inertia ixx="0.000017012" ixy="0.0" ixz="0.0" iyy="0.000013258" iyz="0.0" izz="0.000009483" />
        </inertial>

        <visual>
            <origin rpy="0 0 0" xyz=" 0 0 0 " />
            <geometry>
                <mesh filename="package://mustar_arm_description/meshes/ax12_box.stl" scale="0.001 0.001 0.001" />
            </geometry>
            <material name="Black" />
        </visual>
        <collision>
            <origin rpy="0 0 0" xyz="0.0 0.0 -0.01241" />
            <geometry>
                <mesh filename="package://mustar_arm_description/meshes/ax12_box.stl" scale="0.001 0.001 0.001" />
            </geometry>
        </collision>
    </link>
    <gazebo reference="gripper_servo_link">
        <material>Gazebo/Black</material>
        <selfCollide>true</selfCollide>
        <gravity>true</gravity>
        <!--<mu1>100000.0</mu1>
        <mu2>100000.0</mu2>
        <kp>100000000.0</kp>
        <kd>1.0</kd>-->
    </gazebo>
    <!-- finger 1 -->
    <joint name="gripper_joint" type="revolute">
        <origin rpy="0 0 0" xyz="0 0 0" />
        <axis xyz="0 1 0" />
        <limit effort="30" lower="-0.40" upper="0.7" velocity="0.785" />
        <parent link="gripper_servo_link" />
        <child link="gripper_active_link" />
    </joint>
    <link name="gripper_active_link">
        
<inertial>
            <mass value="0.010" />
            <origin xyz="0 0 0" />
            <inertia ixx="0.000001" ixy="0.0" ixz="0.0" iyy="0.000001" iyz="0.0" izz="0.000001" />
        </inertial>

        <visual>
            <origin rpy="0 0 0" xyz=" 0 0 0 " />
            <geometry>
                <mesh filename="package://turtlebot_arm_description/meshes/F2.stl" scale="0.001 0.001 0.001" />
            </geometry>
            <material name="White" />
        </visual>
        <collision>
            <origin rpy="0 0 0" xyz="0.0 0.0 0.00775" />
            <geometry>
                <mesh filename="package://turtlebot_arm_description/meshes/F2.stl" scale="0.001 0.001 0.001" />
            </geometry>
        </collision>
    </link>
    <joint name="gripper_active_finger_joint" type="fixed">
        <origin rpy="3.14159 0 0" xyz="-0.013 0.017 0.0295" />
        <parent link="gripper_active_link" />
        <child link="gripper_active_finger_link" />
    </joint>
    <link name="gripper_active_finger_link">
        
<inertial>
            <mass value="0.009" />
            <origin xyz="0 0 0" />
            <inertia ixx="9.21675e-06" ixy="0" ixz="0" iyy="9.615e-06" iyz="0" izz="1.33575e-06" />
        </inertial>

        <visual>
            <origin rpy="0 0 0" xyz=" 0 0 0 " />
            <geometry>
                <mesh filename="package://mustar_arm_description/meshes/finger_active.stl" scale="0.001 0.001 0.001" />
            </geometry>
            <material name="Green" />
        </visual>

        <collision name="finger_collision">
            <origin rpy="0 0 0" xyz="0.054 0.017 0.0125" />
            <geometry>
                <mesh filename="package://mustar_arm_description/meshes/finger_active.stl" scale="0.001 0.001 0.001" />
            </geometry>
        </collision>


    </link>
    <gazebo reference="gripper_active_finger_link">
    <sensor name="finger_contacts" type="contact">
        <contact>
          <collision>gripper_active_link_fixed_joint_lump__finger_collision_collision_1</collision>
        </contact>
        <plugin name="gazebo_ros_bumper_controller" filename="libgazebo_ros_bumper.so">
          <always_on>true</always_on>
          <robotNamespace>/</robotNamespace>
          <bumperTopicName>bumper_states</bumperTopicName>
          <frameName>gripper_active_finger_link</frameName>
          <visualize>true</visualize>
          <update_rate>10.0</update_rate>        
        </plugin>
    </sensor>
        <material>Gazebo/Green</material>
        <selfCollide>true</selfCollide>
        <gravity>true</gravity>
        <mu1>10000.0</mu1>
        <mu2>10000.0</mu2>

    </gazebo>
    <joint name="gripper_static_joint" type="fixed">
        <origin rpy="0 3.14159 0" xyz="0 0 -0.0415" />
        <parent link="gripper_servo_link" />
        <child link="gripper_static_link" />
    </joint>
    <link name="gripper_static_link">
        
<inertial>
            <mass value="0.005" />
            <origin xyz="0 0 0" />
            <inertia ixx="2.94166666667e-07" ixy="0" ixz="0" iyy="8.62083333333e-07" iyz="0" izz="6.35416666667e-07" />
        </inertial>

        <visual>
            <origin rpy="0 0 0" xyz=" 0 0 0 " />
            <geometry>
                <mesh filename="package://mustar_arm_description/meshes/F3.stl" scale="0.001 0.001 0.001" />
            </geometry>
            <material name="White" />
        </visual>
        <collision>
            <origin rpy="0 0 0" xyz="0.0 0.0 -0.0045" />
            <geometry>
                <mesh filename="package://mustar_arm_description/meshes/F3.stl" scale="0.001 0.001 0.001" />
            </geometry>
        </collision>
    </link>
    <gazebo reference="gripper_static_link">
        <material>Gazebo/White</material>
        <selfCollide>true</selfCollide>
        <gravity>true</gravity>
        <mu1>10000.0</mu1>
        <mu2>10000.0</mu2>
    </gazebo>
    <joint name="gripper_static_finger_joint" type="fixed">
        <origin rpy="0 0 3.14159" xyz="0.013 0.017 0" />
        <parent link="gripper_static_link" />
        <child link="gripper_static_finger_link" />
    </joint>
    <link name="gripper_static_finger_link">
        
<inertial>
            <mass value="0.0075" />
            <origin xyz="0 0 0" />
            <inertia ixx="5.17938125e-06" ixy="0" ixz="0" iyy="5.79625625e-06" iyz="0" izz="8.28125e-07" />
        </inertial>

        <visual>
            <origin rpy="0 0 0" xyz=" 0 0 0 " />
            <geometry>
                <mesh filename="package://mustar_arm_description/meshes/finger_static.stl" scale="0.001 0.001 0.001" />
            </geometry>
            <material name="Green" />
        </visual>
        <collision>
            <origin rpy="0 0 0" xyz="0.0455 0.017 0.0065" />
            <geometry>
                <mesh filename="package://mustar_arm_description/meshes/finger_static.stl" scale="0.001 0.001 0.001" />
            </geometry>
        </collision>
    </link>
    <gazebo reference="gripper_static_finger_link">
        <material>Gazebo/Green</material>
        <selfCollide>true</selfCollide>
        <gravity>true</gravity>
        <mu1>10000.0</mu1>
        <mu2>10000.0</mu2>
    </gazebo>
    <link name="end_effector_link" />
    <joint name="end_effector_link_joint" type="fixed">
        <origin rpy="-1.571 -0.0 -0.001" xyz="0.066 0 -0.007" />
        <parent link="gripper_servo_link" />
        <child link="end_effector_link" />
    </joint>
    <!--
  <material name="White">
    <color rgba="0.87 0.90 0.87 1.0"/>
  </material>
  <material name="Black">
    <color rgba="0.08 0.08 0.08 1.0"/>
  </material>
  <material name="Gray">
    <color rgba="0.2 0.2 0.21 1.0"/>
  </material>
  <material name="Green">
    <color rgba="0.22 0.32 0.14 1.0"/>
  </material>
-->
    <!-- As we don't have here a turtlebot base, add a base_link link as its location reference -->
    <!--<link name="base_link"/>-->
    <link name="head_base_link" />
    <joint name="head_base_joint" type="fixed">
        <origin xyz="-0.113 0.0 0.793" />
        <parent link="base_link" />
        <child link="head_base_link" />
    </joint>
    <joint name="head_low_joint" type="fixed">
        <origin rpy="0 0 0" xyz="0.002 0 0.019" />
        <parent link="head_base_link" />
        <child link="head_low_link" />
    </joint>
    <link name="head_low_link">
        
<inertial>
            <mass value="0.025" />
            <origin xyz="0 0 0" />
            <inertia ixx="2.37301283333e-05" ixy="0" ixz="0" iyy="3.11474408333e-05" iyz="0" izz="7.5826875e-06" />
        </inertial>

        <visual>
            <origin rpy="0 0 0" xyz="0 0 0" />
            <geometry>
                <mesh filename="package://mustar_head_description/meshes/head_low.stl" scale="0.001 0.001 0.001" />
            </geometry>
            <material name="White" />
        </visual>
        <collision>
            <origin rpy="0 0 0" xyz="-0.015 0.0 0.003" />
            <geometry>
                <box size="0.06 0.13 0.0063" />
            </geometry>
        </collision>
    </link>
    <gazebo reference="head_low_link">
        <material>Gazebo/White</material>
        <selfCollide>true</selfCollide>
        <gravity>true</gravity>
    </gazebo>
    <joint name="head_1_servo_joint" type="fixed">
        <origin rpy="1.570795 0 1.570795" xyz="0 0 0" />
        <parent link="head_base_link" />
        <child link="head_1_servo_link" />
    </joint>
    <link name="head_1_servo_link">
        
<inertial>
            <mass value="0.055" />
            <origin xyz="0 0 0" />
            <inertia ixx="0.000017012" ixy="0.0" ixz="0.0" iyy="0.000013258" iyz="0.0" izz="0.000009483" />
        </inertial>

        <visual>
            <origin rpy="0 0 0" xyz=" 0 0 0 " />
            <geometry>
                <mesh filename="package://mustar_head_description/meshes/ax12_box.stl" scale="0.001 0.001 0.001" />
            </geometry>
            <material name="Black" />
        </visual>
        <collision>
            <origin rpy="0 0 0" xyz="0.0 0.0 -0.01241" />
            <geometry>
                <box size="0.025 0.038 0.04762" />
            </geometry>
        </collision>
    </link>
    <gazebo reference="head_1_servo_link">
        <material>Gazebo/Black</material>
        <selfCollide>true</selfCollide>
        <gravity>true</gravity>
    </gazebo>
    <joint name="head_pan_joint" type="revolute">
        <origin rpy="-1.570795 1.570795 3.14159" xyz="0 0.019 0" />
        <axis xyz="0 0 -1" />
        <limit effort="30" lower="-2.617" upper="2.617" velocity="1.571" />
        <dynamics friction="0.13" />
        <parent link="head_1_servo_link" />
        <child link="head_pan_link" />
    </joint>
    <link name="head_pan_link">
        
<inertial>
            <mass value="0.008" />
            <origin xyz="0 0 0" />
            <inertia ixx="4.70666666667e-07" ixy="0" ixz="0" iyy="1.37933333333e-06" iyz="0" izz="1.01666666667e-06" />
        </inertial>

        <visual>
            <origin rpy="0 0 0" xyz=" 0 0 0 " />
            <geometry>
                <mesh filename="package://mustar_head_description/meshes/F3.stl" scale="0.001 0.001 0.001" />
            </geometry>
            <material name="White" />
        </visual>
        <collision>
            <origin rpy="0 0 0" xyz="0.0 0.0 -0.0045" />
            <geometry>
                <box size="0.025 0.038 0.009" />
            </geometry>
        </collision>
    </link>
    <gazebo reference="head_pan_link">
        <material>Gazebo/White</material>
        <selfCollide>true</selfCollide>
        <gravity>true</gravity>
    </gazebo>
    <joint name="head_2_servo_joint" type="fixed">
        <origin rpy="0 3.14159 3.14159" xyz="0 0 -0.0375" />
        <parent link="head_pan_link" />
        <child link="head_2_servo_link" />
    </joint>
    <link name="head_2_servo_link">
        
<inertial>
            <mass value="0.055" />
            <origin xyz="0 0 0" />
            <inertia ixx="0.000017012" ixy="0.0" ixz="0.0" iyy="0.000013258" iyz="0.0" izz="0.000009483" />
        </inertial>

        <visual>
            <origin rpy="0 0 0" xyz=" 0 0 0 " />
            <geometry>
                <mesh filename="package://mustar_head_description/meshes/ax12_box.stl" scale="0.001 0.001 0.001" />
            </geometry>
            <material name="Black" />
        </visual>
        <collision>
            <origin rpy="0 0 0" xyz="0.0 0.0 -0.01241" />
            <geometry>
                <box size="0.025 0.038 0.04762" />
            </geometry>
        </collision>
    </link>
    <gazebo reference="head_2_servo_link">
        <material>Gazebo/Black</material>
        <selfCollide>true</selfCollide>
        <gravity>true</gravity>
    </gazebo>
    <joint name="head_lift_joint" type="revolute">
        <origin rpy="0 0 3.14159" xyz="0 0 0" />
        <axis xyz="0 1 0" />
        <limit effort="30" lower="-2.617" upper="2.617" velocity="1.571" />
        <dynamics friction="0.13" />
        <parent link="head_2_servo_link" />
        <child link="head_lift_link" />
    </joint>
    <link name="head_lift_link">
        
<inertial>
            <mass value="0.008" />
            <origin xyz="0 0 0" />
            <inertia ixx="2.9736726e-06" ixy="0" ixz="0" iyy="2.26666666667e-06" iyz="0" izz="4.04033926667e-06" />
        </inertial>

        <visual>
            <origin rpy="0 0 0" xyz="0 0 0" />
            <geometry>
                <mesh filename="package://mustar_head_description/meshes/head_high.stl" scale="0.001 0.001 0.001" />
            </geometry>
            <material name="White" />
        </visual>
        <collision>
            <origin rpy="0 0 0" xyz="0.0 0.0 0.015" />
            <geometry>
                <box size="0.03 0.05 0.05861" />
            </geometry>
        </collision>
    </link>
    <gazebo reference="head_lift_link">
        <material>Gazebo/White</material>
        <selfCollide>true</selfCollide>
        <gravity>true</gravity>
    </gazebo>
    <!--<astra_top_fixed parent="head_2_head_high_link" name="head_2_astra_top" color="${color}">
    <origin xyz="0.00825 0 ${HEAD_HIGH_HEIGHT}" rpy="0 0 0"/>
  </astra_top_fixed>-->
    <!-- 
    These properties must be observed by any machine
    that wants to be defined as a turtlebot. Refer
    to the REP for more details.
    
    http://www.ros.org/reps/rep-0119.html
   -->
    <link name="base_footprint" />
    <!--
       Base link is set at the bottom of the base mould.
       This is done to be compatible with the way base link
       was configured for turtlebot 1. Refer to
       https://github.com/turtlebot/turtlebot/issues/40
       To put the base link at the more oft used wheel
       axis, set the z-distance from the base_footprint
       to 0.352.
      -->
    <joint name="base_joint" type="fixed">
        <origin rpy="0 0 0" xyz="0 0 0.0102" />
        <parent link="base_footprint" />
        <child link="base_link" />
    </joint>
    <link name="base_link">
        <visual>
            <geometry>
                <!-- new mesh -->
                <mesh filename="package://kobuki_description/meshes/main_body.dae" />
            </geometry>
            <origin rpy="0 0 0" xyz="0.001 0 0.05199" />
        </visual>
        <collision name="base">
            <geometry>
                <cylinder length="0.10938" radius="0.178" />
            </geometry>
            <origin rpy="0 0 0" xyz="0.0 0 0.05949" />
        </collision>
        
<inertial>
            <!-- COM experimentally determined -->
            <origin xyz="0.01 0 0" />
            <mass value="2.4" />
            <!-- 2.4/2.6 kg for small/big battery pack -->
            <!-- Kobuki's inertia tensor is approximated by a cylinder with homogeneous mass distribution
             More details: http://en.wikipedia.org/wiki/List_of_moment_of_inertia_tensors
             m = 2.4 kg; h = 0.09 m; r = 0.175 m
             ixx = 1/12 * m * (3 * r^2 + h^2)
             iyy = 1/12 * m * (3 * r^2 + h^2)
             izz = 1/2 * m * r^2
          -->
            <inertia ixx="0.019995" ixy="0.0" ixz="0.0" iyy="0.019995" iyz="0.0" izz="0.03675" />
        </inertial>

    </link>
    <joint name="wheel_left_joint" type="continuous">
        <parent link="base_link" />
        <child link="wheel_left_link" />
        <origin rpy="-1.570795 0 0" xyz="0.00 0.115 0.0250" />
        <axis xyz="0 0 1" />
    </joint>
    <link name="wheel_left_link">
        <visual>
            <geometry>
                <mesh filename="package://kobuki_description/meshes/wheel.dae" />
            </geometry>
            <origin rpy="0 0 0" xyz="0 0 0" />
        </visual>
        <collision>
            <geometry>
                <cylinder length="0.0206" radius="0.0352" />
            </geometry>
            <origin rpy="0 0 0" xyz="0 0 0" />
        </collision>
        
<inertial>
            <mass value="0.01" />
            <origin xyz="0 0 0" />
            <inertia ixx="0.001" ixy="0.0" ixz="0.0" iyy="0.001" iyz="0.0" izz="0.001" />
        </inertial>

    </link>
    <joint name="wheel_right_joint" type="continuous">
        <parent link="base_link" />
        <child link="wheel_right_link" />
        <origin rpy="-1.570795 0 0" xyz="0.00 -0.115 0.0250" />
        <axis xyz="0 0 1" />
    </joint>
    <link name="wheel_right_link">
        <visual>
            <geometry>
                <mesh filename="package://kobuki_description/meshes/wheel.dae" />
            </geometry>
            <origin rpy="0 0 0" xyz="0 0 0" />
        </visual>
        <collision>
            <geometry>
                <cylinder length="0.0206" radius="0.0350" />
            </geometry>
            <origin rpy="0 0 0" xyz="0 0 0" />
        </collision>
        
<inertial>
            <mass value="0.01" />
            <origin xyz="0 0 0" />
            <inertia ixx="0.001" ixy="0.0" ixz="0.0" iyy="0.001" iyz="0.0" izz="0.001" />
        </inertial>

    </link>
    <joint name="caster_front_joint" type="fixed">
        <parent link="base_link" />
        <child link="caster_front_link" />
        <origin rpy="-1.570795 0 0" xyz="0.115 0.0 0.007" />
    </joint>
    <link name="caster_front_link">
        <collision>
            <geometry>
                <cylinder length="0.0176" radius="0.017" />
            </geometry>
            <origin rpy="0 0 0" xyz="0 0 0" />
        </collision>
        
<inertial>
            <mass value="0.01" />
            <origin xyz="0 0 0" />
            <inertia ixx="0.001" ixy="0.0" ixz="0.0" iyy="0.001" iyz="0.0" izz="0.001" />
        </inertial>

    </link>
    <joint name="caster_back_joint" type="fixed">
        <parent link="base_link" />
        <child link="caster_back_link" />
        <origin rpy="-1.570795 0 0" xyz="-0.135 0.0 0.009" />
    </joint>
    <link name="caster_back_link">
        <collision>
            <geometry>
                <cylinder length="0.0176" radius="0.017" />
            </geometry>
            <origin rpy="0 0 0" xyz="0 0 0" />
        </collision>
        
<inertial>
            <mass value="0.01" />
            <origin xyz="0 0 0" />
            <inertia ixx="0.001" ixy="0.0" ixz="0.0" iyy="0.001" iyz="0.0" izz="0.001" />
        </inertial>

    </link>
    <!-- Kobuki's sensors -->
    <joint name="gyro_joint" type="fixed">
        <axis xyz="0 1 0" />
        <origin rpy="0 0 0" xyz="0.056 0.062 0.0202" />
        <parent link="base_link" />
        <child link="gyro_link" />
    </joint>
    <link name="gyro_link">
        
<inertial>
            <mass value="0.001" />
            <origin rpy="0 0 0" xyz="0 0 0" />
            <inertia ixx="0.0001" ixy="0" ixz="0" iyy="0.000001" iyz="0" izz="0.0001" />
        </inertial>

    </link>
    <joint name="cliff_sensor_left_joint" type="fixed">
        <origin rpy="0 1.570795 0" xyz="0.08734 0.13601 0.0214" />
        <parent link="base_link" />
        <child link="cliff_sensor_left_link" />
    </joint>
    <link name="cliff_sensor_left_link">
        
<inertial>
            <mass value="0.0001" />
            <origin xyz="0 0 0" />
            <inertia ixx="0.0001" ixy="0.0" ixz="0.0" iyy="0.0001" iyz="0.0" izz="0.0001" />
        </inertial>

    </link>
    <joint name="cliff_sensor_right_joint" type="fixed">
        <origin rpy="0 1.570795 0" xyz="0.085 -0.13601 0.0214" />
        <parent link="base_link" />
        <child link="cliff_sensor_right_link" />
    </joint>
    <link name="cliff_sensor_right_link">
        
<inertial>
            <mass value="0.0001" />
            <origin xyz="0 0 0" />
            <inertia ixx="0.0001" ixy="0.0" ixz="0.0" iyy="0.0001" iyz="0.0" izz="0.0001" />
        </inertial>

    </link>
    <joint name="cliff_sensor_front_joint" type="fixed">
        <origin rpy="0 1.570795 0" xyz="0.156 0.00 0.0214" />
        <parent link="base_link" />
        <child link="cliff_sensor_front_link" />
    </joint>
    <link name="cliff_sensor_front_link">
        
<inertial>
            <mass value="0.0001" />
            <origin xyz="0 0 0" />
            <inertia ixx="0.0001" ixy="0.0" ixz="0.0" iyy="0.0001" iyz="0.0" izz="0.0001" />
        </inertial>

    </link>
    <gazebo reference="wheel_left_link">
        <mu1>1.0</mu1>
        <mu2>1.0</mu2>
        <kp>1000000.0</kp>
        <kd>100.0</kd>
        <minDepth>0.001</minDepth>
        <maxVel>1.0</maxVel>
    </gazebo>
    <gazebo reference="wheel_right_link">
        <mu1>1.0</mu1>
        <mu2>1.0</mu2>
        <kp>1000000.0</kp>
        <kd>100.0</kd>
        <minDepth>0.001</minDepth>
        <maxVel>1.0</maxVel>
    </gazebo>
    <gazebo reference="caster_front_link">
        <mu1>0.0</mu1>
        <mu2>0.0</mu2>
        <kp>1000000.0</kp>
        <kd>100.0</kd>
        <minDepth>0.001</minDepth>
        <maxVel>1.0</maxVel>
    </gazebo>
    <gazebo reference="caster_back_link">
        <mu1>0.0</mu1>
        <mu2>0.0</mu2>
        <kp>1000000.0</kp>
        <kd>100.0</kd>
        <minDepth>0.001</minDepth>
        <maxVel>1.0</maxVel>
    </gazebo>
    <gazebo reference="base_link">
        <mu1>0.3</mu1>
        <mu2>0.3</mu2>
        <sensor name="bumpers" type="contact">
            <always_on>1</always_on>
            <update_rate>50.0</update_rate>
            <visualize>true</visualize>
            <contact>
                <collision>base_footprint_fixed_joint_lump__base_collision</collision>
            </contact>
        </sensor>
    </gazebo>


    <gazebo reference="cliff_sensor_left_link">
        <sensor name="cliff_sensor_left" type="ray">
            <always_on>true</always_on>
            <update_rate>50</update_rate>
            <visualize>true</visualize>
            <ray>
                <scan>
                    <horizontal>
                        <samples>50</samples>
                        <resolution>1.0</resolution>
                        <min_angle>-0.0436</min_angle>
                        <!-- -2.5 degree -->
                        <max_angle>0.0436</max_angle>
                        <!-- 2.5 degree -->
                    </horizontal>
                    <!--            Can't use vertical rays until this bug is resolved: -->
                    <!--            https://bitbucket.org/osrf/gazebo/issue/509/vertical-sensor-doesnt-works -->
                    <!-- 	          <vertical> -->
                    <!-- 	            <samples>50</samples> -->
                    <!-- 	            <resolution>1.0</resolution> -->
                    <!-- 	            <min_angle>-0.0436</min_angle>  -2.5 degree -->
                    <!-- 	            <max_angle>0.0436</max_angle> 2.5 degree -->
                    <!-- 	          </vertical> -->
                </scan>
                <range>
                    <min>0.01</min>
                    <max>0.15</max>
                    <resolution>1.0</resolution>
                </range>
            </ray>
        </sensor>
    </gazebo>
    <gazebo reference="cliff_sensor_right_link">
        <sensor name="cliff_sensor_right" type="ray">
            <always_on>true</always_on>
            <update_rate>50</update_rate>
            <visualize>true</visualize>
            <ray>
                <scan>
                    <horizontal>
                        <samples>50</samples>
                        <resolution>1.0</resolution>
                        <min_angle>-0.0436</min_angle>
                        <!-- -2.5 degree -->
                        <max_angle>0.0436</max_angle>
                        <!-- 2.5 degree -->
                    </horizontal>
                    <!--            Can't use vertical rays until this bug is resolved: -->
                    <!--            https://bitbucket.org/osrf/gazebo/issue/509/vertical-sensor-doesnt-works -->
                    <!-- 	          <vertical> -->
                    <!-- 	            <samples>50</samples> -->
                    <!-- 	            <resolution>1.0</resolution> -->
                    <!-- 	            <min_angle>-0.0436</min_angle>  -2.5 degree -->
                    <!-- 	            <max_angle>0.0436</max_angle> 2.5 degree -->
                    <!-- 	          </vertical> -->
                </scan>
                <range>
                    <min>0.01</min>
                    <max>0.15</max>
                    <resolution>1.0</resolution>
                </range>
            </ray>
        </sensor>
    </gazebo>
    <gazebo reference="cliff_sensor_front_link">
        <sensor name="cliff_sensor_front" type="ray">
            <always_on>true</always_on>
            <update_rate>50</update_rate>
            <visualize>true</visualize>
            <ray>
                <scan>
                    <horizontal>
                        <samples>50</samples>
                        <resolution>1.0</resolution>
                        <min_angle>-0.0436</min_angle>
                        <!-- -2.5 degree -->
                        <max_angle>0.0436</max_angle>
                        <!-- 2.5 degree -->
                    </horizontal>
                    <!-- 	          Can't use vertical rays until this bug is resolved: -->
                    <!--            https://bitbucket.org/osrf/gazebo/issue/509/vertical-sensor-doesnt-works -->
                    <!-- 	          <vertical> -->
                    <!-- 	            <samples>50</samples> -->
                    <!-- 	            <resolution>1.0</resolution> -->
                    <!-- 	            <min_angle>-0.0436</min_angle>  -2.5 degree -->
                    <!-- 	            <max_angle>0.0436</max_angle> 2.5 degree -->
                    <!-- 	          </vertical> -->
                </scan>
                <range>
                    <min>0.01</min>
                    <max>0.15</max>
                    <resolution>1.0</resolution>
                </range>
            </ray>
        </sensor>
    </gazebo>
    <gazebo reference="gyro_link">
        <sensor name="imu" type="imu">
            <always_on>true</always_on>
            <update_rate>50</update_rate>
            <visualize>false</visualize>
            <imu>
                <noise>
                    <type>gaussian</type>
                    <rate>
                        <mean>0.0</mean>
                        <stddev>1.96e-06</stddev>
                        <!-- 0.25 x 0.25 (deg/s) -->
                        <bias_mean>0.0</bias_mean>
                        <bias_stddev>0.0</bias_stddev>
                    </rate>
                    <accel>
                        <!-- not used in the plugin and real robot, hence using tutorial values -->
                        <mean>0.0</mean>
                        <stddev>1.7e-2</stddev>
                        <bias_mean>0.1</bias_mean>
                        <bias_stddev>0.001</bias_stddev>
                    </accel>
                </noise>
            </imu>
        </sensor>
    </gazebo>
    <!--
    <gazebo>
        <plugin filename="libgazebo_ros_kobuki.so" name="kobuki_controller">
            <publish_tf>1</publish_tf>
            <left_wheel_joint_name>wheel_left_joint</left_wheel_joint_name>
            <right_wheel_joint_name>wheel_right_joint</right_wheel_joint_name>
            <wheel_separation>.230</wheel_separation>
            <wheel_diameter>0.070</wheel_diameter>
            <torque>1.0</torque>
            <velocity_command_timeout>0.6</velocity_command_timeout>
            <cliff_sensor_left_name>cliff_sensor_left</cliff_sensor_left_name>
            <cliff_sensor_center_name>cliff_sensor_front</cliff_sensor_center_name>
            <cliff_sensor_right_name>cliff_sensor_right</cliff_sensor_right_name>
            <cliff_detection_threshold>0.04</cliff_detection_threshold>
            <bumper_name>bumpers</bumper_name>
            <imu_name>imu</imu_name>
        </plugin>
    </gazebo>
    -->
    <gazebo>
            <plugin name="differential_drive_controller" filename="libgazebo_ros_diff_drive.so">
                <rosDebugLevel>Debug</rosDebugLevel>
                <publishWheelTF>true</publishWheelTF>
                <robotNamespace>/</robotNamespace>
                <publishTf>1</publishTf>
                <publishWheelJointState>true</publishWheelJointState>
                <alwaysOn>true</alwaysOn>
                <updateRate>100.0</updateRate>
                <legacyMode>true</legacyMode>
                <leftJoint>wheel_left_joint</leftJoint>
                <rightJoint>wheel_right_joint</rightJoint>
                <wheelSeparation>.230</wheelSeparation>
                <wheelDiameter>0.070</wheelDiameter>
                <broadcastTF>1</broadcastTF>
                <wheelTorque>1.0</wheelTorque>
                <wheelAcceleration>1.8</wheelAcceleration>
                <commandTopic>cmd_vel_mux/input/teleop</commandTopic>
                <odometryFrame>odom</odometryFrame> 
                <odometryTopic>odom</odometryTopic> 
                <robotBaseFrame>base_footprint</robotBaseFrame>
                <velocity_command_timeout>0.6</velocity_command_timeout>
            </plugin>
        </gazebo>
    <joint name="pole_bottom_0_joint" type="fixed">
        <origin rpy="0 0 0" xyz="0.12 0.082 0.1028" />
        <parent link="base_link" />
        <child link="pole_bottom_0_link" />
    </joint>
    <link name="pole_bottom_0_link">
        <visual>
            <origin rpy="0 0 0" xyz="0 0 0" />
            <geometry>
                <mesh filename="package://turtlebot_description/meshes/stacks/hexagons/pole_bottom.dae" />
            </geometry>
        </visual>
        <collision>
            <origin rpy="0 0 0" xyz="0 0 0" />
            <geometry>
                <cylinder length="0.0492" radius="0.006" />
            </geometry>
        </collision>
        
<inertial>
            <mass value="0.008" />
            <origin rpy="0 0 0" xyz="0 0 0" />
            <inertia ixx="0.000001686" ixy="0.0" ixz="0.0" iyy="0.000001686" iyz="0.0" izz="0.000000144" />
        </inertial>

    </link>
    <joint name="pole_bottom_1_joint" type="fixed">
        <origin rpy="0 0 0" xyz="0.055 0.12 0.1028" />
        <parent link="base_link" />
        <child link="pole_bottom_1_link" />
    </joint>
    <link name="pole_bottom_1_link">
        <visual>
            <origin rpy="0 0 0" xyz="0 0 0" />
            <geometry>
                <mesh filename="package://turtlebot_description/meshes/stacks/hexagons/pole_bottom.dae" />
            </geometry>
        </visual>
        <collision>
            <origin rpy="0 0 0" xyz="0 0 0" />
            <geometry>
                <cylinder length="0.0492" radius="0.006" />
            </geometry>
        </collision>
        
<inertial>
            <mass value="0.008" />
            <origin rpy="0 0 0" xyz="0 0 0" />
            <inertia ixx="0.000001686" ixy="0.0" ixz="0.0" iyy="0.000001686" iyz="0.0" izz="0.000000144" />
        </inertial>

    </link>
    <joint name="pole_bottom_2_joint" type="fixed">
        <origin rpy="0 0 0" xyz="-0.055 0.12 0.1028" />
        <parent link="base_link" />
        <child link="pole_bottom_2_link" />
    </joint>
    <link name="pole_bottom_2_link">
        <visual>
            <origin rpy="0 0 0" xyz="0 0 0" />
            <geometry>
                <mesh filename="package://turtlebot_description/meshes/stacks/hexagons/pole_bottom.dae" />
            </geometry>
        </visual>
        <collision>
            <origin rpy="0 0 0" xyz="0 0 0" />
            <geometry>
                <cylinder length="0.0492" radius="0.006" />
            </geometry>
        </collision>
        
<inertial>
            <mass value="0.008" />
            <origin rpy="0 0 0" xyz="0 0 0" />
            <inertia ixx="0.000001686" ixy="0.0" ixz="0.0" iyy="0.000001686" iyz="0.0" izz="0.000000144" />
        </inertial>

    </link>
    <joint name="pole_bottom_3_joint" type="fixed">
        <origin rpy="0 0 0" xyz="0.12 -0.082 0.1028" />
        <parent link="base_link" />
        <child link="pole_bottom_3_link" />
    </joint>
    <link name="pole_bottom_3_link">
        <visual>
            <origin rpy="0 0 0" xyz="0 0 0" />
            <geometry>
                <mesh filename="package://turtlebot_description/meshes/stacks/hexagons/pole_bottom.dae" />
            </geometry>
        </visual>
        <collision>
            <origin rpy="0 0 0" xyz="0 0 0" />
            <geometry>
                <cylinder length="0.0492" radius="0.006" />
            </geometry>
        </collision>
        
<inertial>
            <mass value="0.008" />
            <origin rpy="0 0 0" xyz="0 0 0" />
            <inertia ixx="0.000001686" ixy="0.0" ixz="0.0" iyy="0.000001686" iyz="0.0" izz="0.000000144" />
        </inertial>

    </link>
    <joint name="pole_bottom_4_joint" type="fixed">
        <origin rpy="0 0 0" xyz="0.055 -0.12 0.1028" />
        <parent link="base_link" />
        <child link="pole_bottom_4_link" />
    </joint>
    <link name="pole_bottom_4_link">
        <visual>
            <origin rpy="0 0 0" xyz="0 0 0" />
            <geometry>
                <mesh filename="package://turtlebot_description/meshes/stacks/hexagons/pole_bottom.dae" />
            </geometry>
        </visual>
        <collision>
            <origin rpy="0 0 0" xyz="0 0 0" />
            <geometry>
                <cylinder length="0.0492" radius="0.006" />
            </geometry>
        </collision>
        
<inertial>
            <mass value="0.008" />
            <origin rpy="0 0 0" xyz="0 0 0" />
            <inertia ixx="0.000001686" ixy="0.0" ixz="0.0" iyy="0.000001686" iyz="0.0" izz="0.000000144" />
        </inertial>

    </link>
    <joint name="pole_bottom_5_joint" type="fixed">
        <origin rpy="0 0 0" xyz="-0.055 -0.12 0.1028" />
        <parent link="base_link" />
        <child link="pole_bottom_5_link" />
    </joint>
    <link name="pole_bottom_5_link">
        <visual>
            <origin rpy="0 0 0" xyz="0 0 0" />
            <geometry>
                <mesh filename="package://turtlebot_description/meshes/stacks/hexagons/pole_bottom.dae" />
            </geometry>
        </visual>
        <collision>
            <origin rpy="0 0 0" xyz="0 0 0" />
            <geometry>
                <cylinder length="0.0492" radius="0.006" />
            </geometry>
        </collision>
        
<inertial>
            <mass value="0.008" />
            <origin rpy="0 0 0" xyz="0 0 0" />
            <inertia ixx="0.000001686" ixy="0.0" ixz="0.0" iyy="0.000001686" iyz="0.0" izz="0.000000144" />
        </inertial>

    </link>
    <joint name="plate_bottom_joint" type="fixed">
        <origin rpy="0 0 0" xyz="0.02364 0.0 0.1306" />
        <parent link="base_link" />
        <child link="plate_bottom_link" />
    </joint>
    <link name="plate_bottom_link">
        <visual>
            <origin rpy="0 0 0" xyz="0 0 0" />
            <geometry>
                <mesh filename="package://turtlebot_description/meshes/stacks/hexagons/plate_bottom.dae" />
            </geometry>
        </visual>
        <collision>
            <origin rpy="0 0 0" xyz="-0.02364 0 0" />
            <geometry>
                <cylinder length="0.006" radius="0.170" />
            </geometry>
        </collision>
        
<inertial>
            <mass value="0.520" />
            <origin xyz="0 0 0" />
            <inertia ixx="0.003328" ixy="0.0" ixz="0.0" iyy="0.003328" iyz="0.0" izz="0.006656" />
        </inertial>

    </link>
    <joint name="pole_middle_0_joint" type="fixed">
        <origin rpy="0 0 0" xyz="0.0381 0.1505 0.164" />
        <parent link="base_link" />
        <child link="pole_middle_0_link" />
    </joint>
    <link name="pole_middle_0_link">
        <visual>
            <origin rpy="0 3.14159 0" xyz="0 0 0" />
            <geometry>
                <mesh filename="package://turtlebot_description/meshes/stacks/hexagons/pole_middle.dae" />
            </geometry>
        </visual>
        <collision>
            <origin rpy="0 0 0" xyz="0 0 0" />
            <geometry>
                <cylinder length="0.0608" radius="0.006" />
            </geometry>
        </collision>
        
<inertial>
            <mass value="0.012" />
            <origin xyz="0 0 0" />
            <inertia ixx="0.000003805" ixy="0.0" ixz="0.0" iyy="0.000003805" iyz="0.0" izz="0.000000216" />
        </inertial>

    </link>
    <joint name="pole_middle_1_joint" type="fixed">
        <origin rpy="0 0 0" xyz="0.0381 -0.1505 0.164" />
        <parent link="base_link" />
        <child link="pole_middle_1_link" />
    </joint>
    <link name="pole_middle_1_link">
        <visual>
            <origin rpy="0 3.14159 0" xyz="0 0 0" />
            <geometry>
                <mesh filename="package://turtlebot_description/meshes/stacks/hexagons/pole_middle.dae" />
            </geometry>
        </visual>
        <collision>
            <origin rpy="0 0 0" xyz="0 0 0" />
            <geometry>
                <cylinder length="0.0608" radius="0.006" />
            </geometry>
        </collision>
        
<inertial>
            <mass value="0.012" />
            <origin xyz="0 0 0" />
            <inertia ixx="0.000003805" ixy="0.0" ixz="0.0" iyy="0.000003805" iyz="0.0" izz="0.000000216" />
        </inertial>

    </link>
    <joint name="pole_middle_2_joint" type="fixed">
        <origin rpy="0 0 0" xyz="-0.0381 0.1505 0.164" />
        <parent link="base_link" />
        <child link="pole_middle_2_link" />
    </joint>
    <link name="pole_middle_2_link">
        <visual>
            <origin rpy="0 3.14159 0" xyz="0 0 0" />
            <geometry>
                <mesh filename="package://turtlebot_description/meshes/stacks/hexagons/pole_middle.dae" />
            </geometry>
        </visual>
        <collision>
            <origin rpy="0 0 0" xyz="0 0 0" />
            <geometry>
                <cylinder length="0.0608" radius="0.006" />
            </geometry>
        </collision>
        
<inertial>
            <mass value="0.012" />
            <origin xyz="0 0 0" />
            <inertia ixx="0.000003805" ixy="0.0" ixz="0.0" iyy="0.000003805" iyz="0.0" izz="0.000000216" />
        </inertial>

    </link>
    <joint name="pole_middle_3_joint" type="fixed">
        <origin rpy="0 0 0" xyz="-0.0381 -0.1505 0.164" />
        <parent link="base_link" />
        <child link="pole_middle_3_link" />
    </joint>
    <link name="pole_middle_3_link">
        <visual>
            <origin rpy="0 3.14159 0" xyz="0 0 0" />
            <geometry>
                <mesh filename="package://turtlebot_description/meshes/stacks/hexagons/pole_middle.dae" />
            </geometry>
        </visual>
        <collision>
            <origin rpy="0 0 0" xyz="0 0 0" />
            <geometry>
                <cylinder length="0.0608" radius="0.006" />
            </geometry>
        </collision>
        
<inertial>
            <mass value="0.012" />
            <origin xyz="0 0 0" />
            <inertia ixx="0.000003805" ixy="0.0" ixz="0.0" iyy="0.000003805" iyz="0.0" izz="0.000000216" />
        </inertial>

    </link>
    <joint name="plate_middle_joint" type="fixed">
        <origin rpy="0 0 0" xyz="-0.01364 0.0 0.1874" />
        <parent link="base_link" />
        <child link="plate_middle_link" />
    </joint>
    <link name="plate_middle_link">
        <visual>
            <origin rpy="0 0 0" xyz="0 0 0" />
            <geometry>
                <mesh filename="package://turtlebot_description/meshes/stacks/hexagons/plate_middle.dae" />
            </geometry>
        </visual>
        <collision>
            <origin rpy="0 0 0" xyz="0.01364 0.0 0.0" />
            <geometry>
                <cylinder length="0.006" radius="0.170" />
            </geometry>
        </collision>
        
<inertial>
            <mass value="0.520" />
            <origin xyz="0 0 0" />
            <inertia ixx="0.003328" ixy="0.0" ixz="0.0" iyy="0.003328" iyz="0.0" izz="0.006656" />
        </inertial>

    </link>
    <joint name="pole_top_0_joint" type="fixed">
        <origin rpy="0 0 0" xyz="0.0381 0.1505 0.292" />
        <parent link="base_link" />
        <child link="pole_top_0_link" />
    </joint>
    <link name="pole_top_0_link">
        <visual>
            <origin rpy="0 0 0" xyz=" 0 0 0" />
            <geometry>
                <mesh filename="package://turtlebot_description/meshes/stacks/hexagons/pole_top.dae" />
            </geometry>
        </visual>
        <collision>
            <origin rpy="0 0 0" xyz="0 0 0" />
            <geometry>
                <cylinder length="0.2032" radius="0.006" />
            </geometry>
        </collision>
        
<inertial>
            <mass value="0.060" />
            <origin xyz="0 0 0" />
            <inertia ixx="0.000206991" ixy="0.0" ixz="0.0" iyy="0.000206991" iyz="0.0" izz="0.000001080" />
        </inertial>

    </link>
    <joint name="pole_top_1_joint" type="fixed">
        <origin rpy="0 0 0" xyz="0.0381 -0.1505 0.292" />
        <parent link="base_link" />
        <child link="pole_top_1_link" />
    </joint>
    <link name="pole_top_1_link">
        <visual>
            <origin rpy="0 0 0" xyz=" 0 0 0" />
            <geometry>
                <mesh filename="package://turtlebot_description/meshes/stacks/hexagons/pole_top.dae" />
            </geometry>
        </visual>
        <collision>
            <origin rpy="0 0 0" xyz="0 0 0" />
            <geometry>
                <cylinder length="0.2032" radius="0.006" />
            </geometry>
        </collision>
        
<inertial>
            <mass value="0.060" />
            <origin xyz="0 0 0" />
            <inertia ixx="0.000206991" ixy="0.0" ixz="0.0" iyy="0.000206991" iyz="0.0" izz="0.000001080" />
        </inertial>

    </link>
    <joint name="pole_top_2_joint" type="fixed">
        <origin rpy="0 0 0" xyz="-0.0381 0.1505 0.292" />
        <parent link="base_link" />
        <child link="pole_top_2_link" />
    </joint>
    <link name="pole_top_2_link">
        <visual>
            <origin rpy="0 0 0" xyz=" 0 0 0" />
            <geometry>
                <mesh filename="package://turtlebot_description/meshes/stacks/hexagons/pole_top.dae" />
            </geometry>
        </visual>
        <collision>
            <origin rpy="0 0 0" xyz="0 0 0" />
            <geometry>
                <cylinder length="0.2032" radius="0.006" />
            </geometry>
        </collision>
        
<inertial>
            <mass value="0.060" />
            <origin xyz="0 0 0" />
            <inertia ixx="0.000206991" ixy="0.0" ixz="0.0" iyy="0.000206991" iyz="0.0" izz="0.000001080" />
        </inertial>

    </link>
    <joint name="pole_top_3_joint" type="fixed">
        <origin rpy="0 0 0" xyz="-0.0381 -0.1505 0.292" />
        <parent link="base_link" />
        <child link="pole_top_3_link" />
    </joint>
    <link name="pole_top_3_link">
        <visual>
            <origin rpy="0 0 0" xyz=" 0 0 0" />
            <geometry>
                <mesh filename="package://turtlebot_description/meshes/stacks/hexagons/pole_top.dae" />
            </geometry>
        </visual>
        <collision>
            <origin rpy="0 0 0" xyz="0 0 0" />
            <geometry>
                <cylinder length="0.2032" radius="0.006" />
            </geometry>
        </collision>
        
<inertial>
            <mass value="0.060" />
            <origin xyz="0 0 0" />
            <inertia ixx="0.000206991" ixy="0.0" ixz="0.0" iyy="0.000206991" iyz="0.0" izz="0.000001080" />
        </inertial>

    </link>
    <joint name="pole_kinect_0_joint" type="fixed">
        <origin rpy="0 0 0" xyz="-0.1024 0.098 0.2372" />
        <parent link="base_link" />
        <child link="pole_kinect_0_link" />
    </joint>
    <link name="pole_kinect_0_link">
        <visual>
            <origin rpy="0 0 0" xyz="0 0 -0.01" />
            <geometry>
                <mesh filename="package://turtlebot_description/meshes/sensors/sensor_pole.dae" />
            </geometry>
        </visual>
        <collision>
            <origin rpy="0 0 0" xyz="0 0 0" />
            <geometry>
                <cylinder length="0.0936" radius="0.006" />
            </geometry>
        </collision>
        
<inertial>
            <mass value="0.020" />
            <origin xyz="0 0 0" />
            <inertia ixx="0.000014782" ixy="0.0" ixz="0.0" iyy="0.000014782" iyz="0.0" izz="0.000000360" />
        </inertial>

    </link>
    <joint name="pole_kinect_1_joint" type="fixed">
        <origin rpy="0 0 0" xyz="-0.1024 -0.098 0.2372" />
        <parent link="base_link" />
        <child link="pole_kinect_1_link" />
    </joint>
    <link name="pole_kinect_1_link">
        <visual>
            <origin rpy="0 0 0" xyz="0 0 -0.01" />
            <geometry>
                <mesh filename="package://turtlebot_description/meshes/sensors/sensor_pole.dae" />
            </geometry>
        </visual>
        <collision>
            <origin rpy="0 0 0" xyz="0 0 0" />
            <geometry>
                <cylinder length="0.0936" radius="0.006" />
            </geometry>
        </collision>
        
<inertial>
            <mass value="0.020" />
            <origin xyz="0 0 0" />
            <inertia ixx="0.000014782" ixy="0.0" ixz="0.0" iyy="0.000014782" iyz="0.0" izz="0.000000360" />
        </inertial>

    </link>
    <joint name="plate_top_joint" type="fixed">
        <origin rpy="0 0 0" xyz="-0.01364 0.0  0.3966" />
        <parent link="base_link" />
        <child link="plate_top_link" />
    </joint>
    <link name="plate_top_link">
        <visual>
            <origin rpy="0 0 0" xyz="0 0 0" />
            <geometry>
                <mesh filename="package://turtlebot_description/meshes/stacks/hexagons/plate_top.dae" />
            </geometry>
        </visual>
        <collision>
            <origin rpy="0 0 0" xyz="0.01364 0 0" />
            <geometry>
                <cylinder length="0.006" radius="0.170" />
            </geometry>
        </collision>
        
<inertial>
            <mass value="0.520" />
            <origin xyz="0 0 0" />
            <inertia ixx="0.003328" ixy="0.0" ixz="0.0" iyy="0.003328" iyz="0.0" izz="0.006656" />
        </inertial>

    </link>
    <joint name="pole_higher_0_joint" type="fixed">
        <origin rpy="0 0 0" xyz="-0.0503 0.1314 0.501" />
        <parent link="base_link" />
        <child link="pole_higher_0_link" />
    </joint>
    <link name="pole_higher_0_link">
        <visual>
            <origin rpy="0 0 0" xyz=" 0 0 0" />
            <geometry>
                <mesh filename="package://turtlebot_description/meshes/stacks/hexagons/pole_top.dae" />
            </geometry>
        </visual>
        <collision>
            <origin rpy="0 0 0" xyz="0 0 0" />
            <geometry>
                <cylinder length="0.201" radius="0.006" />
            </geometry>
        </collision>
        
<inertial>
            <mass value="0.036" />
            <origin xyz="0 0 0" />
            <inertia ixx="0.000121527" ixy="0" ixz="0" iyy="0.000121527" iyz="0" izz="6.48e-07" />
        </inertial>

    </link>
    <joint name="pole_higher_1_joint" type="fixed">
        <origin rpy="0 0 0" xyz="-0.1024 0.098 0.501" />
        <parent link="base_link" />
        <child link="pole_higher_1_link" />
    </joint>
    <link name="pole_higher_1_link">
        <visual>
            <origin rpy="0 0 0" xyz=" 0 0 0" />
            <geometry>
                <mesh filename="package://turtlebot_description/meshes/stacks/hexagons/pole_top.dae" />
            </geometry>
        </visual>
        <collision>
            <origin rpy="0 0 0" xyz="0 0 0" />
            <geometry>
                <cylinder length="0.201" radius="0.006" />
            </geometry>
        </collision>
        
<inertial>
            <mass value="0.036" />
            <origin xyz="0 0 0" />
            <inertia ixx="0.000121527" ixy="0" ixz="0" iyy="0.000121527" iyz="0" izz="6.48e-07" />
        </inertial>

    </link>
    <joint name="pole_higher_2_joint" type="fixed">
        <origin rpy="0 0 0" xyz="-0.1024 -0.098 0.501" />
        <parent link="base_link" />
        <child link="pole_higher_2_link" />
    </joint>
    <link name="pole_higher_2_link">
        <visual>
            <origin rpy="0 0 0" xyz=" 0 0 0" />
            <geometry>
                <mesh filename="package://turtlebot_description/meshes/stacks/hexagons/pole_top.dae" />
            </geometry>
        </visual>
        <collision>
            <origin rpy="0 0 0" xyz="0 0 0" />
            <geometry>
                <cylinder length="0.201" radius="0.006" />
            </geometry>
        </collision>
        
<inertial>
            <mass value="0.036" />
            <origin xyz="0 0 0" />
            <inertia ixx="0.000121527" ixy="0" ixz="0" iyy="0.000121527" iyz="0" izz="6.48e-07" />
        </inertial>

    </link>
    <joint name="pole_higher_3_joint" type="fixed">
        <origin rpy="0 0 0" xyz="-0.0503 -0.1314 0.501" />
        <parent link="base_link" />
        <child link="pole_higher_3_link" />
    </joint>
    <link name="pole_higher_3_link">
        <visual>
            <origin rpy="0 0 0" xyz=" 0 0 0" />
            <geometry>
                <mesh filename="package://turtlebot_description/meshes/stacks/hexagons/pole_top.dae" />
            </geometry>
        </visual>
        <collision>
            <origin rpy="0 0 0" xyz="0 0 0" />
            <geometry>
                <cylinder length="0.201" radius="0.006" />
            </geometry>
        </collision>
        
<inertial>
            <mass value="0.036" />
            <origin xyz="0 0 0" />
            <inertia ixx="0.000121527" ixy="0" ixz="0" iyy="0.000121527" iyz="0" izz="6.48e-07" />
        </inertial>

    </link>
    <joint name="plate_higher_joint" type="fixed">
        <origin rpy="1.570795 0 -1.570795" xyz="0.02351 0.15579 0.615" />
        <parent link="base_link" />
        <child link="plate_higher_link" />
    </joint>
    <link name="plate_higher_link">
        <visual>
            <origin rpy="0 0 0" xyz="0 0 0" />
            <geometry>
                <mesh filename="package://turtlebot_description/meshes/stacks/hexagons/plate_higher.dae" scale="0.001 0.001 0.001" />
            </geometry>
        </visual>
        <collision>
            <origin rpy="0 0 0" xyz="0 0 0" />
            <geometry>
                <mesh filename="package://turtlebot_description/meshes/stacks/hexagons/plate_higher.dae" scale="0.001 0.001 0.001" />
            </geometry>
        </collision>
        
<inertial>
            <mass value="0.171" />
            <origin xyz="0 0 0" />
            <inertia ixx="0.003328" ixy="0.0" ixz="0.0" iyy="0.003328" iyz="0.0" izz="0.006656" />
        </inertial>

    </link>
    <joint name="pole_monitor_0_joint" type="fixed">
        <origin rpy="0 0 0" xyz="-0.11127 0.057 0.71" />
        <parent link="base_link" />
        <child link="pole_monitor_0_link" />
    </joint>
    <link name="pole_monitor_0_link">
        <visual>
            <origin rpy="0 0 0" xyz=" 0 0 0" />
            <geometry>
                <mesh filename="package://turtlebot_description/meshes/stacks/hexagons/pole_top.dae" />
            </geometry>
        </visual>
        <collision>
            <origin rpy="0 0 0" xyz="0 0 0" />
            <geometry>
                <cylinder length="0.208" radius="0.006" />
            </geometry>
        </collision>
        
<inertial>
            <mass value="0.036" />
            <origin xyz="0 0 0" />
            <inertia ixx="0.000130116" ixy="0" ixz="0" iyy="0.000130116" iyz="0" izz="6.48e-07" />
        </inertial>

    </link>
    <joint name="pole_monitor_1_joint" type="fixed">
        <origin rpy="0 0 0" xyz="-0.11127 -0.057 0.71" />
        <parent link="base_link" />
        <child link="pole_monitor_1_link" />
    </joint>
    <link name="pole_monitor_1_link">
        <visual>
            <origin rpy="0 0 0" xyz=" 0 0 0" />
            <geometry>
                <mesh filename="package://turtlebot_description/meshes/stacks/hexagons/pole_top.dae" />
            </geometry>
        </visual>
        <collision>
            <origin rpy="0 0 0" xyz="0 0 0" />
            <geometry>
                <cylinder length="0.208" radius="0.006" />
            </geometry>
        </collision>
        
<inertial>
            <mass value="0.036" />
            <origin xyz="0 0 0" />
            <inertia ixx="0.000130116" ixy="0" ixz="0" iyy="0.000130116" iyz="0" izz="6.48e-07" />
        </inertial>

    </link>
    <joint name="emergency_switch_joint" type="fixed">
        <origin rpy="1.570795 0 -1.570795" xyz="0.0145 -0.1084 0.556" />
        <parent link="base_link" />
        <child link="emergency_switch_link" />
    </joint>
    <link name="emergency_switch_link">
        <visual>
            <origin rpy="0 0 0" xyz="0 0 0" />
            <geometry>
                <mesh filename="package://turtlebot_description/meshes/stacks/hexagons/emergency_switch.dae" scale="0.001 0.001 0.001" />
            </geometry>
            <material name="Black" />
        </visual>
        <collision>
            <origin rpy="1.570795 0 0" xyz="0.02 0.038 0.02" />
            <geometry>
                <cylinder length="0.10" radius="0.045" />
            </geometry>
        </collision>
        
<inertial>
            <mass value="0.054" />
            <origin xyz="0 0 0" />
            <inertia ixx="7.122375e-06" ixy="0" ixz="0" iyy="7.122375e-06" iyz="0" izz="1.366875e-05" />
        </inertial>

    </link>
    <joint name="monitor_joint" type="fixed">
        <origin rpy="1.570795 0 1.570795" xyz="-0.1064 -0.1225 0.643" />
        <parent link="base_link" />
        <child link="monitor_link" />
    </joint>
    <link name="monitor_link">
        <visual>
            <origin rpy="0 0 0" xyz="0 0 0" />
            <geometry>
                <mesh filename="package://turtlebot_description/meshes/stacks/hexagons/monitor.dae" scale="0.001 0.001 0.001" />
            </geometry>
            <material name="Black" />
        </visual>
        <collision>
            <origin rpy="0 0 0" xyz="0.1225 0.0825 0.0175" />
            <geometry>
                <box size="0.245 0.165 0.035" />
            </geometry>
        </collision>
        
<inertial>
            <mass value="0.466" />
            <origin xyz="0 0 0" />
            <inertia ixx="0.00237854166667" ixy="0" ixz="0" iyy="0.00338820833333" iyz="0" izz="0.00110480833333" />
        </inertial>

    </link>
    <joint name="mic_mount_joint" type="fixed">
        <origin rpy="1.570795 0 0" xyz="-0.016175 0.1476 0.609" />
        <parent link="base_link" />
        <child link="mic_mount_link" />
    </joint>
    <link name="mic_mount_link">
        <visual>
            <origin rpy="0 0 0" xyz="0 0 0" />
            <geometry>
                <mesh filename="package://turtlebot_description/meshes/stacks/hexagons/mic_mount.dae" scale="0.001 0.001 0.001" />
            </geometry>
            <material name="Black" />
        </visual>
        <collision>
            <origin rpy="1.570795 0 0" xyz="0.0162 0.015 0.0162" />
            <geometry>
                <cylinder length="0.03" radius="0.0162" />
            </geometry>
        </collision>
        
<inertial>
            <mass value="0.084" />
            <origin xyz="0 0 0" />
            <inertia ixx="1.181124e-05" ixy="0" ixz="0" iyy="1.181124e-05" iyz="0" izz="1.102248e-05" />
        </inertial>

    </link>
    <joint name="mic_joint" type="fixed">
        <origin rpy="2.61799166667 0 -1.570795" xyz="0.095 0.1476 0.772" />
        <parent link="base_link" />
        <child link="mic_link" />
    </joint>
    <link name="mic_link">
        <visual>
            <origin rpy="0 0 0" xyz="0 0 0" />
            <geometry>
                <mesh filename="package://turtlebot_description/meshes/stacks/hexagons/mic.dae" scale="0.001 0.001 0.001" />
            </geometry>
            <material name="Black" />
        </visual>
        <collision>
            <origin rpy="0 0 0" xyz="0.015 0.05 0.106" />
            <geometry>
                <box size="0.03 0.05 0.212" />
            </geometry>
        </collision>
        
<inertial>
            <mass value="0.133" />
            <origin xyz="0 0 0" />
            <inertia ixx="0.000508104333333" ixy="0" ixz="0" iyy="3.76833333333e-05" iyz="0" izz="0.000525837666667" />
        </inertial>

    </link>
    <!--    <joint name="astra_top_low_joint" type="fixed">
      <origin xyz="-0.09627 -0.072 0.812" rpy="0 0 ${M_PI/2}"/>
      <parent link="${parent}"/>
      <child link="astra_top_low_link"/>
    </joint>  
    <link name="astra_top_low_link">
      <visual>
        <origin xyz="0 0 0" rpy="0 0 0"/>
        <geometry>
          <mesh filename="package://turtlebot_description/meshes/stacks/hexagons/astra_top_low.dae" scale="${M_SCALE} ${M_SCALE} ${M_SCALE}"/>
        </geometry>
        <material name="Black"/>
      </visual>  
      <collision>
        <origin xyz="0.075 0.025 0.015" rpy="0 0 0"/>
        <geometry>
          <box size="0.15 0.05 0.03"/>
        </geometry>
      </collision>
      <xacro:box_inertia length="0.15" width="0.05" height="0.03" mass="0.025"/>
    </link>
-->
    <!--    <joint name="astra_top_high_joint" type="fixed">
      <origin xyz="-0.09627 0.0375 0.864" rpy="0 ${M_PI} ${M_PI/2}"/>
      <parent link="${parent}"/>
      <child link="astra_top_high_link"/>
    </joint>  
    <link name="astra_top_high_link">
      <visual>
        <origin xyz="0 0 0" rpy="0 0 0"/>
        <geometry>
          <mesh filename="package://turtlebot_description/meshes/stacks/hexagons/astra_top_high.dae" scale="${M_SCALE} ${M_SCALE} ${M_SCALE}"/>
        </geometry>
        <material name="Black"/>
      </visual>  
      <collision>
        <origin xyz="0.04 0.02 0.015" rpy="0 0 0"/>
        <geometry>
          <box size="0.08 0.04 0.03"/>
        </geometry>
      </collision>
      <xacro:box_inertia length="0.08" width="0.04" height="0.03" mass="0.0185"/>
    </link>
-->
    <!--    <joint name="astra_top_fake_joint" type="fixed">
      <origin xyz="-0.125 0 0.871" rpy="${M_PI/2} 0 ${M_PI/2}"/>
      <parent link="${parent}"/>
      <child link="astra_top_fake_link"/>
    </joint>  
    <link name="astra_top_fake_link">
      <visual>
        <origin xyz="0 0 0" rpy="0 0 0"/>
        <geometry>
          <mesh filename="package://turtlebot_description/meshes/sensors/astra.dae" scale="0.8 0.8 0.8"/>
        </geometry>
        <material name="Black"/>
      </visual>  
      <collision>
        <origin xyz="0 0.003 0.015" rpy="0 0 ${M_PI/2}"/>
        <geometry>
          <box size="0.0400 0.1650 0.0300"/>
        </geometry>
      </collision>
      
<inertial>
        <mass value="0.564"/>
        <origin xyz="0 0 0"/>
        <inertia ixx="0.003328" ixy="0.0" ixz="0.0"
                 iyy="0.003328" iyz="0.0"
                 izz="0.006656" />
      </inertial>
    </link>
-->
    <joint name="rplidar_a1_joint" type="fixed">
        <origin rpy="3.14159 0 0" xyz="0 0 0.349" />
        <parent link="base_link" />
        <child link="rplidar_a1_link" />
    </joint>
    <link name="rplidar_a1_link">
        <visual>
            <origin rpy="0 0 0" xyz="0 0 0" />
            <geometry>
                <mesh filename="package://turtlebot_description/meshes/stacks/hexagons/rplidar_a1.dae" scale="1 1 1" />
            </geometry>
        </visual>
        <collision>
            <origin rpy="0 0 0" xyz="0 0 0" />
            <geometry>
                <cylinder length="0.006" radius="0.170" />
            </geometry>
        </collision>
        
	<inertial>
            <mass value="0.213" />
            <origin xyz="0 0 0" />
            <inertia ixx="0.000261564" ixy="0" ixz="0" iyy="0.000261564" iyz="0" izz="0.00052185" />
        </inertial>

    </link>
    
    <gazebo reference="base_link">
            <sensor type="ray" name="rplidar">
                <pose>0 0 0 0 0 0</pose>
                <visualize>false</visualize>
                <update_rate>5.5</update_rate>
                <ray>
                    <scan>
                      <horizontal>
                        <samples>360</samples>
                        <resolution>1</resolution>
                        <min_angle>-3</min_angle>
                        <max_angle>3</max_angle>
                      </horizontal>
                    </scan>
                    <range>
                      <min>0.10</min>
                      <max>6.0</max>
                      <resolution>0.01</resolution>
                    </range>
                    <noise>
                      <type>gaussian</type>
                      <mean>0.0</mean>
                      <stddev>0.01</stddev>
                    </noise>
                </ray>
                <plugin name="gazebo_rplidar" filename="libgazebo_ros_laser.so">
                    <topicName>/scan</topicName>
                    <frameName>base_link</frameName>
                </plugin>
            </sensor>
        </gazebo>
    
    
    <joint name="camera_rgb_joint" type="fixed">
        <origin rpy="0 0 0" xyz="0.137 -0.125 0.537" />
        <parent link="base_link" />
        <child link="camera_rgb_frame" />
    </joint>
    <link name="camera_rgb_frame" />
    <joint name="camera_rgb_optical_joint" type="fixed">
        <origin rpy="-1.570795 0 -1.570795" xyz="0 0 0" />
        <parent link="camera_rgb_frame" />
        <child link="camera_rgb_optical_frame" />
    </joint>
    <link name="camera_rgb_optical_frame" />
    <joint name="camera_joint" type="fixed">
        <origin rpy="0 0 0" xyz="0 -0.0125 0" />
        <parent link="camera_rgb_frame" />
        <child link="camera_link" />
    </joint>
    <link name="camera_link">
        <visual>
            <origin rpy="1.570795 0 1.570795" xyz="-0.04 0.02 -0.01" />
            <geometry>
                <mesh filename="package://turtlebot_description/meshes/sensors/astra.dae" scale="0.6 0.6 0.6" />
            </geometry>
        </visual>
        <collision>
            <origin rpy="0 0 0" xyz="0.0 0.0 0.0" />
            <geometry>
                <box size="0.0400 0.1650 0.0300" />
            </geometry>
        </collision>
        
<inertial>
            <mass value="0.564" />
            <origin xyz="0 0 0" />
            <inertia ixx="0.003881243" ixy="0.0" ixz="0.0" iyy="0.000498940" iyz="0.0" izz="0.003879257" />
        </inertial>

    </link>
    <joint name="camera_depth_joint" type="fixed">
        <origin rpy="0 0 0" xyz="0 0.025 0" />
        <parent link="camera_rgb_frame" />
        <child link="camera_depth_frame" />
    </joint>
    <link name="camera_depth_frame" />
    <joint name="camera_depth_optical_joint" type="fixed">
        <origin rpy="-1.570795 0 -1.570795" xyz="0 0 0" />
        <parent link="camera_depth_frame" />
        <child link="camera_depth_optical_frame" />
    </joint>
    <link name="camera_depth_optical_frame" />
    <gazebo reference="camera_link">
        <sensor name="camera" type="depth">
            <always_on>true</always_on>
            <update_rate>20.0</update_rate>
            <camera>
                <horizontal_fov>1.04719666667</horizontal_fov>
                <image>
                    <format>B8G8R8</format>
                    <width>640</width>
                    <height>480</height>
                </image>
                <clip>
                    <near>0.05</near>
                    <far>8.0</far>
                </clip>
            </camera>
            <plugin filename="libgazebo_ros_openni_kinect.so" name="kinect_camera_controller">
                <cameraName>camera</cameraName>
                <alwaysOn>true</alwaysOn>
                <updateRate>10</updateRate>
                <imageTopicName>rgb/image_raw</imageTopicName>
                <depthImageTopicName>depth/image_raw</depthImageTopicName>
                <pointCloudTopicName>depth/points</pointCloudTopicName>
                <cameraInfoTopicName>rgb/camera_info</cameraInfoTopicName>
                <depthImageCameraInfoTopicName>depth/camera_info</depthImageCameraInfoTopicName>
                <frameName>camera_depth_optical_frame</frameName>
                <baseline>0.1</baseline>
                <distortion_k1>0.0</distortion_k1>
                <distortion_k2>0.0</distortion_k2>
                <distortion_k3>0.0</distortion_k3>
                <distortion_t1>0.0</distortion_t1>
                <distortion_t2>0.0</distortion_t2>
                <pointCloudCutoff>0.4</pointCloudCutoff>
            </plugin>
        </sensor>
    </gazebo>
    <joint name="camera_top_rgb_joint" type="fixed">
        <origin rpy="0 0 0" xyz="0.0168 0 0.0615" />
        <parent link="head_lift_link" />
        <child link="camera_top_rgb_frame" />
    </joint>
    <link name="camera_top_rgb_frame" />
    <joint name="camera_top_rgb_optical_joint" type="fixed">
        <origin rpy="-1.570795 0 -1.570795" xyz="0 0 0" />
        <parent link="camera_top_rgb_frame" />
        <child link="camera_top_rgb_optical_frame" />
    </joint>
    <link name="camera_top_rgb_optical_frame" />
    <joint name="camera_top_joint" type="fixed">
        <origin rpy="0 0 0" xyz="0 -0.0125 0" />
        <parent link="camera_top_rgb_frame" />
        <child link="camera_top_link" />
    </joint>
    <link name="camera_top_link">
        <visual>
            <origin rpy="1.570795 0 1.570795" xyz="-0.04 0.02 -0.01" />
            <geometry>
                <mesh filename="package://turtlebot_description/meshes/sensors/astra.dae" scale="0.6 0.6 0.6" />
            </geometry>
        </visual>
        <collision>
            <origin rpy="0 0 0" xyz="-0.035 0.0175 -0.002" />
            <geometry>
                <box size="0.0400 0.1650 0.0300" />
            </geometry>
        </collision>
        
<inertial>
            <mass value="0.564" />
            <origin xyz="0 0 0" />
            <inertia ixx="0.003881243" ixy="0.0" ixz="0.0" iyy="0.000498940" iyz="0.0" izz="0.003879257" />
        </inertial>

    </link>
    <joint name="camera_top_depth_joint" type="fixed">
        <origin rpy="0 0 0" xyz="0 0.025 0" />
        <parent link="camera_top_rgb_frame" />
        <child link="camera_top_depth_frame" />
    </joint>
    <link name="camera_top_depth_frame" />
    <joint name="camera_top_depth_optical_joint" type="fixed">
        <origin rpy="-1.570795 0 -1.570795" xyz="0 0 0" />
        <parent link="camera_top_depth_frame" />
        <child link="camera_top_depth_optical_frame" />
    </joint>
    <link name="camera_top_depth_optical_frame" />
    <gazebo reference="camera_top_link">
        <sensor name="camera" type="depth">
            <always_on>true</always_on>
            <update_rate>20.0</update_rate>
            <camera>
                <horizontal_fov>1.04719666667</horizontal_fov>
                <image>
                    <format>B8G8R8</format>
                    <width>640</width>
                    <height>480</height>
                </image>
                <clip>
                    <near>0.05</near>
                    <far>8.0</far>
                </clip>
            </camera>
            <plugin filename="libgazebo_ros_openni_kinect.so" name="kinect_top_camera_controller">
                <cameraName>camera</cameraName>
                <alwaysOn>true</alwaysOn>
                <updateRate>10</updateRate>
                <imageTopicName>top/rgb/image_raw</imageTopicName>
                <depthImageTopicName>top/depth/image_raw</depthImageTopicName>
                <pointCloudTopicName>top/depth/points</pointCloudTopicName>
                <cameraInfoTopicName>top/rgb/camera_info</cameraInfoTopicName>
                <depthImageCameraInfoTopicName>top/depth/camera_info</depthImageCameraInfoTopicName>
                <frameName>camera_top_depth_optical_frame</frameName>
                <baseline>0.1</baseline>
                <distortion_k1>0.0</distortion_k1>
                <distortion_k2>0.0</distortion_k2>
                <distortion_k3>0.0</distortion_k3>
                <distortion_t1>0.0</distortion_t1>
                <distortion_t2>0.0</distortion_t2>
                <pointCloudCutoff>0.4</pointCloudCutoff>
            </plugin>
        </sensor>
    </gazebo>
    
<transmission name="trans_arm_1_F3_joint">
        <type>transmission_interface/SimpleTransmission</type>
        <joint name="arm_1_F3_joint">
            <hardwareInterface>hardware_interface/PositionJointInterface</hardwareInterface>
        </joint>
        <actuator name="arm_1_F3_joint_motor">
            <hardwareInterface>hardware_interface/PositionJointInterface</hardwareInterface>
            <mechanicalReduction>1</mechanicalReduction>
        </actuator>
    </transmission>
    <transmission name="trans_arm_2_F4_joint">
        <type>transmission_interface/SimpleTransmission</type>
        <joint name="arm_2_F4_joint">
            <hardwareInterface>hardware_interface/PositionJointInterface</hardwareInterface>
        </joint>
        <actuator name="arm_2_F4_joint_motor">
            <hardwareInterface>hardware_interface/PositionJointInterface</hardwareInterface>
            <mechanicalReduction>1</mechanicalReduction>
        </actuator>
    </transmission>
    <transmission name="trans_arm_3_F4_joint">
        <type>transmission_interface/SimpleTransmission</type>
        <joint name="arm_3_F4_joint">
            <hardwareInterface>hardware_interface/PositionJointInterface</hardwareInterface>
        </joint>
        <actuator name="arm_3_F4_joint_motor">
            <hardwareInterface>hardware_interface/PositionJointInterface</hardwareInterface>
            <mechanicalReduction>1</mechanicalReduction>
        </actuator>
    </transmission>
    <transmission name="trans_arm_4_F3_joint">
        <type>transmission_interface/SimpleTransmission</type>
        <joint name="arm_4_F3_joint">
            <hardwareInterface>hardware_interface/PositionJointInterface</hardwareInterface>
        </joint>
        <actuator name="arm_4_F3_joint_motor">
            <hardwareInterface>hardware_interface/PositionJointInterface</hardwareInterface>
            <mechanicalReduction>1</mechanicalReduction>
        </actuator>
    </transmission>
    <transmission name="trans_arm_5_F3_joint">
        <type>transmission_interface/SimpleTransmission</type>
        <joint name="arm_5_F3_joint">
            <hardwareInterface>hardware_interface/PositionJointInterface</hardwareInterface>
        </joint>
        <actuator name="arm_5_F3_joint_motor">
            <hardwareInterface>hardware_interface/PositionJointInterface</hardwareInterface>
            <mechanicalReduction>1</mechanicalReduction>
        </actuator>
    </transmission>
    <transmission name="trans_arm_6_F3_joint">
        <type>transmission_interface/SimpleTransmission</type>
        <joint name="arm_6_F3_joint">
            <hardwareInterface>hardware_interface/PositionJointInterface</hardwareInterface>
        </joint>
        <actuator name="arm_6_F3_joint_motor">
            <hardwareInterface>hardware_interface/PositionJointInterface</hardwareInterface>
            <mechanicalReduction>1</mechanicalReduction>
        </actuator>
    </transmission>
    <transmission name="trans_gripper_joint">
        <type>transmission_interface/SimpleTransmission</type>
        <joint name="gripper_joint">
            <hardwareInterface>hardware_interface/PositionJointInterface</hardwareInterface>
        </joint>
        <actuator name="gripper_joint_motor">
            <hardwareInterface>hardware_interface/PositionJointInterface</hardwareInterface>
            <mechanicalReduction>1</mechanicalReduction>
        </actuator>
    </transmission>
    <transmission name="trans_head_pan_joint">
        <type>transmission_interface/SimpleTransmission</type>
        <joint name="head_pan_joint">
            <hardwareInterface>hardware_interface/PositionJointInterface</hardwareInterface>
        </joint>
        <actuator name="head_pan_joint_motor">
            <hardwareInterface>hardware_interface/PositionJointInterface</hardwareInterface>
            <mechanicalReduction>1</mechanicalReduction>
        </actuator>
    </transmission>
    <transmission name="trans_head_lift_joint">
        <type>transmission_interface/SimpleTransmission</type>
        <joint name="head_lift_joint">
            <hardwareInterface>hardware_interface/PositionJointInterface</hardwareInterface>
        </joint>
        <actuator name="head_lift_joint_motor">
            <hardwareInterface>hardware_interface/PositionJointInterface</hardwareInterface>
            <mechanicalReduction>1</mechanicalReduction>
        </actuator>
    </transmission>
    <transmission name="trans_wheel_left_joint">
        <type>transmission_interface/SimpleTransmission</type>
        <joint name="wheel_left_joint">
            <hardwareInterface>hardware_interface/EffortJointInterface</hardwareInterface>
        </joint>
        <actuator name="wheel_left_joint_motor">
            <hardwareInterface>hardware_interface/EffortJointInterface</hardwareInterface>
            <mechanicalReduction>1</mechanicalReduction>
        </actuator>
    </transmission>
    <transmission name="trans_wheel_right_joint">
        <type>transmission_interface/SimpleTransmission</type>
        <joint name="wheel_right_joint">
            <hardwareInterface>hardware_interface/EffortJointInterface</hardwareInterface>
        </joint>
        <actuator name="wheel_right_joint_motor">
            <hardwareInterface>hardware_interface/EffortJointInterface</hardwareInterface>
            <mechanicalReduction>1</mechanicalReduction>
        </actuator>
    </transmission>
    <gazebo>
        <plugin name="gazebo_ros_control" filename="libgazebo_ros_control.so">
            <robotNamespace>/</robotNamespace>
            <!--<robotNamespace>/mugator_manip</robotNamespace>-->
            <robotSimType>gazebo_ros_control/DefaultRobotHWSim</robotSimType>
            <legacyModeNS>true</legacyModeNS>
        </plugin>
    </gazebo>
</robot>
